Workbook

Sheet challenge_report_2022_10-2025-1
A1: Organization name | B1: Hackathon name | C1: Hackathon url | D1: Hackathon published date | E1: Total participant count | F1: Total valid submissions (excluding spam) | G1: In person vs virtual | H1: Column 1 | I1: Column 2
A2: BrickHack | B2: BrickHack X | C2: https://brickhack-x.devpost.com | D2: 2024-02-12 12:19:49 -0500 | E2: 176 | F2: 53 | G2: College/ University | H2: =VALUE(LEFT(D2,4)) -> 2024
A3: Minnetonka High School | B3: TonkaHacks 2022 | C3: https://tonkahacks.devpost.com | D3: 2022-11-12 15:33:51 -0500 | E3: 37 | F3: 18 | G3: High School | H3: =VALUE(LEFT(D3,4)) -> 2022
A4: Protocol Labs | B4: Protocol Labs (Filecoin Green)-Sustainable Blockchain Hackathon | C4: https://sbsboston.devpost.com | D4: 2023-02-01 16:37:29 -0500 | E4: 427 | F4: 39 | G4: Private Sector | H4: =VALUE(LEFT(D4,4)) -> 2023
A5: Women in Computer Science | B5: HopperHacks 2023 | C5: https://hopperhacks-2023.devpost.com | D5: 2023-01-30 15:18:33 -0500 | E5: 127 | F5: 24 | G5: College/ University | H5: =VALUE(LEFT(D5,4)) -> 2023
A6: ACM Hack | B6: Hack Internal | C6: https://lairtxhtoh.devpost.com | D6: 2023-03-04 13:16:41 -0500 | E6: 4 | F6: 0 | G6: College/ University | H6: =VALUE(LEFT(D6,4)) -> 2023
A7: MegaHackathonLeague | B7: MegaHack<>Kinetik Challenge | C7: https://megahackkinetik.devpost.com | D7: 2024-10-25 19:11:41 -0400 | E7: 32 | F7: 16 | G7: Civic | H7: =VALUE(LEFT(D7,4)) -> 2024
A8: Society of Computer Developers | B8: WayneHacks | C8: https://waynehacks.devpost.com | D8: 2023-02-25 23:42:11 -0500 | E8: 50 | F8: 16 | G8: College/ University | H8: =VALUE(LEFT(D8,4)) -> 2023
A9: Humane Interface Design Enterprise | B9: Winter WonderHack 2023 | C9: https://winter-wonderhack-2023.devpost.com | D9: 2023-03-15 16:27:45 -0400 | E9: 8 | F9: 4 | G9: College/ University | H9: =VALUE(LEFT(D9,4)) -> 2023
A10: iata | B10: IATA ONE Record Hackathon – hosted by Lufthansa Cargo | C10: https://onerecord-fra.devpost.com | D10: 2022-12-06 05:11:46 -0500 | E10: 215 | F10: 20 | G10: Private Sector | H10: =VALUE(LEFT(D10,4)) -> 2022
A11: Rock Ridge High School | B11: Phoenix Hacks | C11: https://phoenix-hacks.devpost.com | D11: 2022-12-03 10:16:19 -0500 | E11: 72 | F11: 23 | G11: High School | H11: =VALUE(LEFT(D11,4)) -> 2022
A12: Brandeis University | B12: DeisHacks 2023 | C12: https://deishacks-2023.devpost.com | D12: 2023-02-03 14:43:38 -0500 | E12: 117 | F12: 33 | G12: College/ University | H12: =VALUE(LEFT(D12,4)) -> 2023
A13: Sahyadri Open Source Community | B13: Hacknight 2023 | C13: https://hacknight-23.devpost.com | D13: 2023-10-13 11:05:33 -0400 | E13: 336 | F13: 30 | G13: College/ University | H13: =VALUE(LEFT(D13,4)) -> 2023
... A24: Spartan Hackers | B24: Code Green | C24: https://code-green.devpost.com | D24: 2022-10-07 11:48:33 -0400 | E24: 121 | F24: 10 | G24: College/ University | H24: =VALUE(LEFT(D24,4)) -> 2022
A25: Hack the North | B25: Hack the North 2024 | C25: https://hackthenorth2024.devpost.com | D25: 2024-08-30 13:01:47 -0400 | E25: 835 | F25: 235 | H25: =VALUE(LEFT(D25,4)) -> 2024
A26: Hack the North | B26: Hack the North 2025 | C26: https://hackthenorth2025.devpost.com | D26: 2025-09-04 00:22:10 -0400 | E26: 873 | F26: 261 | H26: =VALUE(LEFT(D26,4)) -> 2025
A27: Minnetronix | B27: IoT Hack Day 2022 | C27: https://iot-hack-day-2022.devpost.com | D27: 2022-10-17 20:31:50 -0400 | E27: 4 | F27: 0 | G27: Civic | H27: =VALUE(LEFT(D27,4)) -> 2022
A28: Sego Lily Hacks | B28: Sego Lily Hacks | C28: https://sego-lily-hacks-2022.devpost.com | D28: 2022-10-01 22:56:17 -0400 | E28: 72 | F28: 16 | H28: =VALUE(LEFT(D28,4)) -> 2022
A29: Iroquois Ridge High School | B29: Hack The Ridge 2022 | C29: https://hack-the-ridge-2022.devpost.com | D29: 2022-12-09 23:26:36 -0500 | E29: 69 | F29: 26 | G29: High School | H29: =VALUE(LEFT(D29,4)) -> 2022
A30: Wellesley CS Club | B30: WHACK 2022 | C30: https://whack-2022.devpost.com | D30: 2022-11-08 09:48:26 -0500 | E30: 89 | F30: 24 | G30: College/ University | H30: =VALUE(LEFT(D30,4)) -> 2022
A31: Brook Codes | B31: Brook Codes 2022 | C31: https://brook-codes-2022.devpost.com | D31: 2022-10-02 17:24:36 -0400 | E31: 122 | F31: 44 | G31: High School | H31: =VALUE(LEFT(D31,4)) -> 2022
A32: TAMU Datathon | B32: TAMU Datathon 2022 | C32: https://tamudatathon2022.devpost.com | D32: 2022-10-02 20:20:49 -0400 | E32: 219 | F32: 75 | G32: College/ University | H32: =VALUE(LEFT(D32,4)) -> 2022
A33: HackAlphaX | B33: NextStep Hacks 2024 | C33: https://nextstep2024.devpost.com | D33: 2023-10-11 22:13:10 -0400 | E33: 403 | F33: 32 | G33: High School | H33: =VALUE(LEFT(D33,4)) -> 2023
A34: Global DevSlam | B34: FutureHack | C34: https://futurehack.devpost.com | D34: 2022-10-03 10:52:53 -0400 | E34: 141 | F34: 26 | G34: Private Sector | H34: =VALUE(LEFT(D34,4)) -> 2022
A35: ultra.io | B35: Ultra Uniq NFT PFP Hackathon | C35: https://ultrauniqhackathon.devpost.com | D35: 2022-10-03 07:06:22 -0400 | E35: 178 | F35: 41 | H35: =VALUE(LEFT(D35,4)) -> 2022
A36: M&T Bank | B36: Meet & Hack 2 | C36: https://meet-hack-2.devpost.com | D36: 2022-11-07 13:36:35 -0500 | E36: 64 | F36: 19 | G36: College/ University | H36: =VALUE(LEFT(D36,4)) -> 2022
A37: CCAD | B37: Hack@Davidson I | C37: https://hackdavidson.devpost.com | D37: 2022-10-18 18:09:54 -0400 | E37: 65 | F37: 12 | G37: College/ University | H37: =VALUE(LEFT(D37,4)) -> 2022
A38: Ohio University Entrepreneurship Club | B38: HackPalachia 2023 | C38: https://hackpalachiaou.devpost.com | D38: 2023-03-03 16:38:43 -0500 | E38: 32 | F38: 14 | G38: College/ University | H38: =VALUE(LEFT(D38,4)) -> 2023
A39: VandyHacks | B39: VandyHacks IX | C39: https://vandyhacks-ix.devpost.com | D39: 2022-10-21 13:29:21 -0400 | E39: 121 | F39: 35 | G39: College/ University | H39: =VALUE(LEFT(D39,4)) -> 2022
A40: SingleStore | B40: SingleStore Database Hackathon | C40: https://singlestore.devpost.com | D40: 2022-10-03 10:00:02 -0400 | E40: 536 | F40: 42 | H40: =VALUE(LEFT(D40,4)) -> 2022
A41: NUS High School | B41: NUSH HACK 2022 | C41: https://nushhack2022.devpost.com | D41: 2022-11-09 08:28:04 -0500 | E41: 22 | F41: 11 | G41: High School | H41: =VALUE(LEFT(D41,4)) -> 2022
A42: Treasure Hacks | B42: Treasure Hacks 3.0 | C42: https://treasure-hacks-3-0.devpost.com | D42: 2022-10-05 20:02:42 -0400 | E42: 573 | F42: 80 | G42: College/ University | H42: =VALUE(LEFT(D42,4)) -> 2022
A43: City of Syracuse | B43: Syracuse Open Data Day | C43: https://syracuse-open-data-day.devpost.com | D43: 2023-10-04 10:33:55 -0400 | E43: 52 | F43: 8 | G43: Civic | H43: =VALUE(LEFT(D43,4)) -> 2023
A44: Business Meets Tech @WHU | B44: BusinessMeetsTech IdeaHack! 2022 | C44: https://bmt-ideahack-2022.devpost.com | D44: 2022-10-04 14:15:19 -0400 | E44: 3 | F44: 1 | G44: College/ University | H44: =VALUE(LEFT(D44,4)) -> 2022
A45: zappar | B45: ZappARthon | C45: https://zapparthon.devpost.com | D45: 2022-11-08 12:40:38 -0500 | E45: 434 | F45: 34 | G45: Private Sector | H45: =VALUE(LEFT(D45,4)) -> 2022
A46: XDC Network | B46: XDC DeFi Hackathon | C46: https://xdc.devpost.com | D46: 2022-10-07 11:24:48 -0400 | E46: 473 | F46: 40 | H46: =VALUE(LEFT(D46,4)) -> 2022
A47: Mizzou Computing Association | B47: TigerHacks 2022 | C47: https://th22.devpost.com | D47: 2022-10-23 20:24:50 -0400 | E47: 312 | F47: 80 | G47: College/ University | H47: =VALUE(LEFT(D47,4)) -> 2022
A48: Amazon | B48: AWS Data Exchange for APIs Challenge | C48: https://awsdataexchange4apis.devpost.com | D48: 2022-10-10 10:00:25 -0400 | E48: 726 | F48: 30 | H48: =VALUE(LEFT(D48,4)) -> 2022
A49: BigRed//Hacks | B49: Cornell BigRed//Hacks 2022 | C49: https://bigred-hacks-2022.devpost.com | D49: 2022-10-13 00:36:56 -0400 | E49: 204 | F49: 57 | G49: College/ University | H49: =VALUE(LEFT(D49,4)) -> 2022
A50: Open Web Academy | B50: Open Web House Puerto Vallarta | C50: https://open-web-house.devpost.com | D50: 2022-10-25 19:22:04 -0400 | E50: 54 | F50: 5 | G50: Civic | H50: =VALUE(LEFT(D50,4)) -> 2022
...

Sheet Sheet3
A1: Year | B1: Total Hackathons | C1: Total Participants | D1: Avg Participants | E1: Total Valid Submissions | F1: Avg Valid Submissions | G1: YoY Growth (%)
A2: 2022 | B2: =COUNTIF('challenge_report_2022_10-2025-1'!H:H, A2) -> 294 | C2: =SUMIF('challenge_report_2022_10-2025-1'!H:H, A2, 'challenge_report_2022_10-2025-1'!E:E) -> 46388 | D2: =AVERAGEIF('challenge_report_2022_10-2025-1'!H:H, A2, 'challenge_report_2022_10-2025-1'!E:E) -> 157.78231 | E2: =SUMIF('challenge_report_2022_10-2025-1'!H:H, A2, 'challenge_report_2022_10-2025-1'!F:F) -> 8135 | F2: =AVERAGEIF('challenge_report_2022_10-2025-1'!H:H, A2, 'challenge_report_2022_10-2025-1'!F:F) -> 27.670068 | G2: -%
A3: 2023 | B3: =COUNTIF('challenge_report_2022_10-2025-1'!H:H, A3) -> 1266 | C3: =SUMIF('challenge_report_2022_10-2025-1'!H:H, A3, 'challenge_report_2022_10-2025-1'!E:E) -> 225143 | D3: =AVERAGEIF('challenge_report_2022_10-2025-1'!H:H, A3, 'challenge_report_2022_10-2025-1'!E:E) -> 177.83807 | E3: =SUMIF('challenge_report_2022_10-2025-1'!H:H, A3, 'challenge_report_2022_10-2025-1'!F:F) -> 37683 | F3: =AVERAGEIF('challenge_report_2022_10-2025-1'!H:H, A3, 'challenge_report_2022_10-2025-1'!F:F) -> 29.765403 | G3: =IF(A3>MIN($A$2:$A$10), (C3 - OFFSET(C3, -1, 0)) / OFFSET(C3, -1, 0), "") -> 3.853475
A4: 2024 | B4: =COUNTIF('challenge_report_2022_10-2025-1'!H:H, A4) -> 1376 | C4: =SUMIF('challenge_report_2022_10-2025-1'!H:H, A4, 'challenge_report_2022_10-2025-1'!E:E) -> 324326 | D4: =AVERAGEIF('challenge_report_2022_10-2025-1'!H:H, A4, 'challenge_report_2022_10-2025-1'!E:E) -> 235.70203 | E4: =SUMIF('challenge_report_2022_10-2025-1'!H:H, A4, 'challenge_report_2022_10-2025-1'!F:F) -> 47509 | F4: =AVERAGEIF('challenge_report_2022_10-2025-1'!H:H, A4, 'challenge_report_2022_10-2025-1'!F:F) -> 34.52689 | G4: =IF(A4>MIN($A$2:$A$10), (C4 - OFFSET(C4, -1, 0)) / OFFSET(C4, -1, 0), "") -> 0.44053335
A5: 2025 | B5: =COUNTIF('challenge_report_2022_10-2025-1'!H:H, A5) -> 1546 | C5: =SUMIF('challenge_report_2022_10-2025-1'!H:H, A5, 'challenge_report_2022_10-2025-1'!E:E) -> 542578 | D5: =AVERAGEIF('challenge_report_2022_10-2025-1'!H:H, A5, 'challenge_report_2022_10-2025-1'!E:E) -> 350.95602 | E5: =SUMIF('challenge_report_2022_10-2025-1'!H:H, A5, 'challenge_report_2022_10-2025-1'!F:F) -> 66502 | F5: =AVERAGEIF('challenge_report_2022_10-2025-1'!H:H, A5, 'challenge_report_2022_10-2025-1'!F:F) -> 43.015524 | G5: =IF(A5>MIN($A$2:$A$10), (C5 - OFFSET(C5, -1, 0)) / OFFSET(C5, -1, 0), "") -> 0.67294019

Sheet Key Accounts 2025
A1: name | B1: Hackathon name | C1: Hackathon url | D1: Total participant count | E1: Hackathon published date | F1: Total valid submissions | G1: In person vs virtual
A2: Atlassian | B2: Forge Quest: Bonus Level | C2: https://forgequest.devpost.com | D2: 2371 | E2: 2025-05-20 12:09:25 -0400 | F2: 283
A3: Atlassian | B3: Codegeist 2025: Atlassian Williams Racing Edition | C3: https://codegeistxawr.devpost.com | D3: 750 | E3: 2025-10-08 12:19:52 -0400 | F3: 6 | G3: Ongoing
A4: AWS | B4: AWS AI Agent Global Hackathon | C4: https://aws-agent-hackathon.devpost.com | D4: 9558 | E4: 2025-09-08 14:59:17 -0400 | F4: 610
A5: Amazon | B5: AWS Presents: Breaking Barriers Virtual Challenge | C5: https://aws-breaking-barriers.devpost.com | D5: 2336 | E5: 2025-04-21 14:32:09 -0400 | F5: 102
A6: Amazon | B6: AWS Lambda Hackathon | C6: https://awslambdahackathon.devpost.com | D6: 3725 | E6: 2025-06-03 11:39:22 -0400 | F6: 331
A7: Kiro | B7: Code with Kiro Hackathon | C7: https://kiro.devpost.com | D7: 10012 | E7: 2025-07-14 08:59:42 -0400 | F7: 552
A8: AWS Hong Kong | B8: AWS AI Hackathon Hong Kong | C8: https://aws-hong-kong-hackathon.devpost.com | D8: 841 | E8: 2025-08-15 00:20:33 -0400 | F8: 129
A9: Amazon | B9: Rift Rewind Hackathon | C9: https://riftrewind.devpost.com | D9: 2268 | E9: 2025-09-15 12:03:45 -0400 | F9: 5 | G9: Ongoing
A10: AWS & NVIDIA | B10: Agentic AI Unleashed: AWS & NVIDIA Hackathon | C10: https://nvidia-aws.devpost.com | D10: 1861 | E10: 2025-09-29 11:01:35 -0400 | F10: 10 | G10: Ongoing
A11: Google | B11: Agent Development Kit Hackathon with Google Cloud | C11: https://googlecloudmultiagents.devpost.com | D11: 10397 | E11: 2025-04-09 11:00:28 -0400 | F11: 476
A12: Google | B12: GKE Turns 10 Hackathon | C12: https://gketurns10.devpost.com | D12: 4759 | E12: 2025-08-04 10:49:58 -0400 | F12: 133
A13: Google | B13: AI in Action | C13: https://ai-in-action.devpost.com | D13: 6729 | E13: 2025-04-09 10:30:34 -0400 | F13: 295
A14: Google | B14: Google Maps Platform Awards | C14: https://googlemapsplatformawards.devpost.com | D14: 3951 | E14: 2025-05-20 11:55:20 -0400 | F14: 416
A15: Google | B15: Baseline Tooling Hackathon | C15: https://baseline.devpost.com | D15: 2962 | E15: 2025-09-02 11:56:46 -0400 | F15: 172
A16: Google | B16: AI Accelerate: Unlocking New Frontiers | C16: https://ai-accelerate.devpost.com | D16: 2792 | E16: 2025-09-16 11:59:59 -0400 | F16: 171
A17: Google | B17: Google Chrome Built-in AI Challenge 2025 | C17: https://googlechromeai2025.devpost.com | D17: 13821 | E17: 2025-09-09 11:50:20 -0400 | F17: 564 | G17: ongoing
A18: Google | B18: Cloud Run Hackathon | C18: https://run.devpost.com | D18: 2250 | E18: 2025-10-06 11:54:30 -0400 | F18: 24 | G18: Ongoing
A19: Meta | B19: Meta Horizon Creator Competition: Mobile Genre Showdown | C19: https://mhcp-mobile-genre-competition.devpost.com | D19: 1551 | E19: 2025-03-11 13:29:02 -0400 | F19: 281
A20: Meta | B20: Meta Horizon Creator Competition: Elevate Your Mobile World | C20: https://mhcp-mobile-update-competition.devpost.com | D20: 1414 | E20: 2025-06-20 12:54:35 -0400 | F20: 185
A21: Meta | B21: Meta Horizon Creator Competition: Open Source Champions | C21: https://mhcp-open-source-competition.devpost.com | D21: 1233 | E21: 2025-08-14 12:46:35 -0400 | F21: 329
A22: Meta | B22: Meta Horizon Creator Competition: Mobile Genre Showdown - Reloaded | C22: https://mhcp-mobile-genre-2.devpost.com | D22: 1598 | E22: 2025-09-18 17:03:25 -0400 | F22: 83
A23: Salesforce | B23: Agentforce Virtual Hackathon | C23: https://agentforcehackathon.devpost.com | D23: 7235 | E23: 2025-03-04 14:04:48 -0500 | F23: 225
A24: Tableau | B24: Tableau Next Virtual Hackathon | C24: https://tableau.devpost.com | D24: 4531 | E24: 2025-07-24 12:23:07 -0400 | F24: 99
D25: =SUM(D2:D24) -> 98945

Sheet Overview
A1: Here's a summary of the categories and their distribution: • College/University: This category represents the largest portion, with 2,162 hackathons (54.13%). • High School: High schools hosted 952 hackathons, accounting for 23.84% of the total. • Private Sector: The private sector organized 616 hackathons, making up 15.42% of the events. • Civic: Civic organizations hosted 264 hackathons, which is 6.61% of the total.
